Workbook

Sheet README
A1: AI DC Capex 모델 — 빅4 (MSFT · GOOGL · AMZN · META)
A2: 작성 기준일 2026-09-10. 2026년 7월 말 2분기 실적 발표 기준 가이던스 반영.
A4: 시트 구성
A5: Consolidated: 4사 합산, 회사별 비중·조달 갭
A6: MSFT / GOOGL / AMZN / META: 회사별 매출→OCF→Capex→조달 모델 (동일 구조)
A8: 범례
A9: 파란 글씨 + 노란 셀 = 입력값 (수정 가능)
A10: 검정 = 계산식, 초록 = 타 시트 링크, 주황 셀 = 조달 갭 출력
A12: 주의사항
A13: 1. Capex 정의가 회사마다 다름: MSFT=현금PP&E+금융리스, META=현금PP&E+금융리스 원금상환, GOOGL/AMZN=현금PP&E만. 합산 시 정의 차이 존재.
A14: 2. MSFT는 6월 결산 → CY 환산은 근사치. 2026E $175B는 리스 재분류 후 금액(경제적 투자 ~$190B).
A15: 3. 2025A 매출·OCF·현금·부채는 근사치이므로 10-K/10-Q로 확인 후 교체 권장.
... A31: 출처: Counterpoint 2Q26 점유율(SK 50/삼성 33/마이크론 18), TrendForce 2026-06(Rubin Ultra 384GB, ASIC 216/288GB, 2027 계약가 급등), Silicon Analysts 2026-08 스택 가격

Sheet Scenario
A1: 시나리오 (Bear / Base / Bull)
A2: B4 셀에 1·2·3 입력 → 회사 capex, HBM 가격·용량·믹스, 공급사 점유율이 일괄 전환. 각 레버는 Base 입력값 대비 조정(배수 또는 %p 가산).
A4: 선택 (1=Bear, 2=Base, 3=Bull) | B4: 2 | C4: =CHOOSE(B4,"Bear","Base","Bull") -> Base
A6: 레버 | B6: 케이스 | C6: 2026E | D6: 2027E | E6: 2028E | F6: 2029E | G6: 2030E | H6: 메모
A7: Capex 성장률 조정 (2027E~, %p 가산) | H7: Bear: AI 수요 둔화·FCF 압박으로 2027부터 증가율 둔화 / Bull: 2027 큰 폭 증가 코멘트(GOOGL) 현실화
B8: Bear | C8: 0 | D8: -0.1 | E8: -0.1 | F8: -0.08 | G8: -0.05
B9: Base | C9: 0 | D9: 0 | E9: 0 | F9: 0 | G9: 0
B10: Bull | C10: 0 | D10: 0.1 | E10: 0.1 | F10: 0.08 | G10: 0.05
A11: → 적용값 | B11: =$C$4 -> Base | C11: =INDEX(C8:C10,$B$4) -> 0 | D11: =INDEX(D8:D10,$B$4) -> 0 | E11: =INDEX(E8:E10,$B$4) -> 0 | F11: =INDEX(F8:F10,$B$4) -> 0 | G11: =INDEX(G8:G10,$B$4) -> 0
A13: AI 가속기 비중 조정 (%p 가산) | H13: 서버 capex 중 GPU/ASIC 시스템 비중
B14: Bear | C14: -0.05 | D14: -0.05 | E14: -0.05 | F14: -0.05 | G14: -0.05
B15: Base | C15: 0 | D15: 0 | E15: 0 | F15: 0 | G15: 0
B16: Bull | C16: 0.05 | D16: 0.05 | E16: 0.05 | F16: 0.05 | G16: 0.05
A17: → 적용값 | B17: =$C$4 -> Base | C17: =INDEX(C14:C16,$B$4) -> 0 | D17: =INDEX(D14:D16,$B$4) -> 0 | E17: =INDEX(E14:E16,$B$4) -> 0 | F17: =INDEX(F14:F16,$B$4) -> 0 | G17: =INDEX(G14:G16,$B$4) -> 0
A19: HBM $/GB 배수 | H19: Bull: TrendForce 2027 계약가 '수 배' 상승 반영 / Bear: 공급 증설(삼성·마이크론 capa)과 CXMT 진입으로 가격 정상화
B20: Bear | C20: 0.9 | D20: 0.75 | E20: 0.7 | F20: 0.7 | G20: 0.7
B21: Base | C21: 1 | D21: 1 | E21: 1 | F21: 1 | G21: 1
B22: Bull | C22: 1.1 | D22: 1.5 | E22: 1.4 | F22: 1.3 | G22: 1.2
A23: → 적용값 | B23: =$C$4 -> Base | C23: =INDEX(C20:C22,$B$4) -> 1 | D23: =INDEX(D20:D22,$B$4) -> 1 | E23: =INDEX(E20:E22,$B$4) -> 1 | F23: =INDEX(F20:F22,$B$4) -> 1 | G23: =INDEX(G20:G22,$B$4) -> 1
A25: HBM GB/칩 배수 (용량 업그레이드 속도) | H25: Bear: Rubin Ultra 384GB 지연·ASIC 용량 상향 지연 / Bull: 추론용 KV캐시 수요로 칩당 HBM 추가 상향
B26: Bear | C26: 0.95 | D26: 0.9 | E26: 0.9 | F26: 0.9 | G26: 0.9
B27: Base | C27: 1 | D27: 1 | E27: 1 | F27: 1 | G27: 1
B28: Bull | C28: 1.05 | D28: 1.1 | E28: 1.15 | F28: 1.15 | G28: 1.15
A29: → 적용값 | B29: =$C$4 -> Base | C29: =INDEX(C26:C28,$B$4) -> 1 | D29: =INDEX(D26:D28,$B$4) -> 1 | E29: =INDEX(E26:E28,$B$4) -> 1 | F29: =INDEX(F26:F28,$B$4) -> 1 | G29: =INDEX(G26:G28,$B$4) -> 1
A31: 가속기 ASP 배수 | H31: ASP 높으면 같은 capex로 대수 감소 → HBM 감소 (Bear: 메모리 원가 전가로 ASP 상승)
B32: Bear | C32: 1.05 | D32: 1.05 | E32: 1.05 | F32: 1.05 | G32: 1.05
B33: Base | C33: 1 | D33: 1 | E33: 1 | F33: 1 | G33: 1
B34: Bull | C34: 0.95 | D34: 0.95 | E34: 0.95 | F34: 0.95 | G34: 0.95
A35: → 적용값 | B35: =$C$4 -> Base | C35: =INDEX(C32:C34,$B$4) -> 1 | D35: =INDEX(D32:D34,$B$4) -> 1 | E35: =INDEX(E32:E34,$B$4) -> 1 | F35: =INDEX(F32:F34,$B$4) -> 1 | G35: =INDEX(G32:G34,$B$4) -> 1
A37: 빅4 글로벌 비중 조정 (%p 가산) | H37: Bull: 네오클라우드·소버린·OpenAI 자체 인프라 등 빅4 외 수요 확대 → 빅4 비중 하락 = 글로벌 시장 확대
B38: Bear | C38: 0.05 | D38: 0.05 | E38: 0.05 | F38: 0.05 | G38: 0.05
B39: Base | C39: 0 | D39: 0 | E39: 0 | F39: 0 | G39: 0
B40: Bull | C40: -0.05 | D40: -0.05 | E40: -0.05 | F40: -0.05 | G40: -0.05
A41: → 적용값 | B41: =$C$4 -> Base | C41: =INDEX(C38:C40,$B$4) -> 0 | D41: =INDEX(D38:D40,$B$4) -> 0 | E41: =INDEX(E38:E40,$B$4) -> 0 | F41: =INDEX(F38:F40,$B$4) -> 0 | G41: =INDEX(G38:G40,$B$4) -> 0
A43: 삼성 점유율 조정 (%p 가산, SK hynix에서 이전) | H43: 삼성 HBM4 램프 성공 여부. 마이크론은 고정
B44: Bear | C44: -0.05 | D44: -0.08 | E44: -0.08 | F44: -0.08 | G44: -0.08
B45: Base | C45: 0 | D45: 0 | E45: 0 | F45: 0 | G45: 0
B46: Bull | C46: 0.05 | D46: 0.08 | E46: 0.1 | F46: 0.1 | G46: 0.1
A47: → 적용값 | B47: =$C$4 -> Base | C47: =INDEX(C44:C46,$B$4) -> 0 | D47: =INDEX(D44:D46,$B$4) -> 0 | E47: =INDEX(E44:E46,$B$4) -> 0 | F47: =INDEX(F44:F46,$B$4) -> 0 | G47: =INDEX(G44:G46,$B$4) -> 0
A50: 시나리오 비교 (스냅샷 — 입력값 변경 시 자동 갱신되지 않음, 2026-09-10 기준)
...

Sheet Consolidated
A1: 빅4 합산 — Capex & 자금조달 ($B)
A2: MSFT·GOOGL·AMZN·META 시트 합산. 달력연도 기준. MSFT는 FY→CY 환산 근사.
A3: ="현재 시나리오: "&Scenario!C4 -> 현재 시나리오: Base
A4: 항목 | B4: 2025A | C4: 2026E | D4: 2027E | E4: 2028E | F4: 2029E | G4: 2030E | H4: 5년 합계(26E~30E)
A5: 합산 Capex
A6: 총 Capex | B6: =MSFT!B14+GOOGL!B14+AMZN!B14+META!B14 -> 412 | C6: =MSFT!C14+GOOGL!C14+AMZN!C14+META!C14 -> 732.5 | D6: =MSFT!D14+GOOGL!D14+AMZN!D14+META!D14 -> 907.75 | E6: =MSFT!E14+GOOGL!E14+AMZN!E14+META!E14 -> 1031.0425 | F6: =MSFT!F14+GOOGL!F14+AMZN!F14+META!F14 -> 1124.5372 | G6: =MSFT!G14+GOOGL!G14+AMZN!G14+META!G14 -> 1180.764 | H6: =SUM(C6:G6) -> 4976.5937
A7: 서버·칩 | B7: =MSFT!B19+GOOGL!B19+AMZN!B19+META!B19 -> 237.05 | C7: =MSFT!C19+GOOGL!C19+AMZN!C19+META!C19 -> 444.875 | D7: =MSFT!D19+GOOGL!D19+AMZN!D19+META!D19 -> 551.7125 | E7: =MSFT!E19+GOOGL!E19+AMZN!E19+META!E19 -> 621.96362 | F7: =MSFT!F19+GOOGL!F19+AMZN!F19+META!F19 -> 678.57903 | G7: =MSFT!G19+GOOGL!G19+AMZN!G19+META!G19 -> 712.50798 | H7: =SUM(C7:G7) -> 3009.6381
A8: DC·전력·네트워크 | B8: =MSFT!B20+GOOGL!B20+AMZN!B20+META!B20 -> 174.95 | C8: =MSFT!C20+GOOGL!C20+AMZN!C20+META!C20 -> 287.625 | D8: =MSFT!D20+GOOGL!D20+AMZN!D20+META!D20 -> 356.0375 | E8: =MSFT!E20+GOOGL!E20+AMZN!E20+META!E20 -> 409.07887 | F8: =MSFT!F20+GOOGL!F20+AMZN!F20+META!F20 -> 445.95812 | G8: =MSFT!G20+GOOGL!G20+AMZN!G20+META!G20 -> 468.25603 | H8: =SUM(C8:G8) -> 1966.9555
A9: Capex YoY | C9: =IF(B6=0,0,C6/B6-1) -> 0.77791262 | D9: =IF(C6=0,0,D6/C6-1) -> 0.23924915 | E9: =IF(D6=0,0,E6/D6-1) -> 0.13582209 | F9: =IF(E6=0,0,F6/E6-1) -> 0.090679725 | G9: =IF(F6=0,0,G6/F6-1) -> 0.05
A10: 매출 합계 | B10: =MSFT!B8+GOOGL!B8+AMZN!B8+META!B8 -> 1625 | C10: =MSFT!C8+GOOGL!C8+AMZN!C8+META!C8 -> 1941.55 | D10: =MSFT!D8+GOOGL!D8+AMZN!D8+META!D8 -> 2228.2008 | E10: =MSFT!E8+GOOGL!E8+AMZN!E8+META!E8 -> 2504.1885 | F10: =MSFT!F8+GOOGL!F8+AMZN!F8+META!F8 -> 2768.8467 | G10: =MSFT!G8+GOOGL!G8+AMZN!G8+META!G8 -> 3033.8487 | H10: =SUM(C10:G10) -> 12476.635
A11: OCF 합계 | B11: =MSFT!B10+GOOGL!B10+AMZN!B10+META!B10 -> 552.27 | C11: =MSFT!C10+GOOGL!C10+AMZN!C10+META!C10 -> 647.5266 | D11: =MSFT!D10+GOOGL!D10+AMZN!D10+META!D10 -> 753.86908 | E11: =MSFT!E10+GOOGL!E10+AMZN!E10+META!E10 -> 847.83869 | F11: =MSFT!F10+GOOGL!F10+AMZN!F10+META!F10 -> 938.61638 | G11: =MSFT!G10+GOOGL!G10+AMZN!G10+META!G10 -> 1029.745 | H11: =SUM(C11:G11) -> 4217.5957
A12: Capex / 매출 | B12: =IF(B10=0,0,B6/B10) -> 0.25353846 | C12: =IF(C10=0,0,C6/C10) -> 0.37727589 | D12: =IF(D10=0,0,D6/D10) -> 0.40739147 | E12: =IF(E10=0,0,E6/E10) -> 0.41172719 | F12: =IF(F10=0,0,F6/F10) -> 0.40613918 | G12: =IF(G10=0,0,G6/G10) -> 0.38919674 | H12: =IF(H10=0,0,H6/H10) -> 0.39887308
A13: Capex / OCF | B13: =IF(B11=0,0,B6/B11) -> 0.74601191 | C13: =IF(C11=0,0,C6/C11) -> 1.1312277 | D13: =IF(D11=0,0,D6/D11) -> 1.2041215 | E13: =IF(E11=0,0,E6/E11) -> 1.2160833 | F13: =IF(F11=0,0,F6/F11) -> 1.1980796 | G13: =IF(G11=0,0,G6/G11) -> 1.1466567 | H13: =IF(H11=0,0,H6/H11) -> 1.1799599
A15: 합산 자금조달
A16: 현금 capex | B16: =MSFT!B23+GOOGL!B23+AMZN!B23+META!B23 -> 375.05 | C16: =MSFT!C23+GOOGL!C23+AMZN!C23+META!C23 -> 660.825 | D16: =MSFT!D23+GOOGL!D23+AMZN!D23+META!D23 -> 807.15188 | E16: =MSFT!E23+GOOGL!E23+AMZN!E23+META!E23 -> 915.22969 | F16: =MSFT!F23+GOOGL!F23+AMZN!F23+META!F23 -> 998.36459 | G16: =MSFT!G23+GOOGL!G23+AMZN!G23+META!G23 -> 1048.2828 | H16: =SUM(C16:G16) -> 4429.854
A17: 리스/JV 조달 | B17: =MSFT!B22+GOOGL!B22+AMZN!B22+META!B22 -> 36.95 | C17: =MSFT!C22+GOOGL!C22+AMZN!C22+META!C22 -> 71.675 | D17: =MSFT!D22+GOOGL!D22+AMZN!D22+META!D22 -> 100.59812 | E17: =MSFT!E22+GOOGL!E22+AMZN!E22+META!E22 -> 115.81281 | F17: =MSFT!F22+GOOGL!F22+AMZN!F22+META!F22 -> 126.17256 | G17: =MSFT!G22+GOOGL!G22+AMZN!G22+META!G22 -> 132.48119 | H17: =SUM(C17:G17) -> 546.73968
A18: 신규 부채 발행 | B18: =MSFT!B28+GOOGL!B28+AMZN!B28+META!B28 -> 0 | C18: =MSFT!C28+GOOGL!C28+AMZN!C28+META!C28 -> 150 | D18: =MSFT!D28+GOOGL!D28+AMZN!D28+META!D28 -> 140 | E18: =MSFT!E28+GOOGL!E28+AMZN!E28+META!E28 -> 135 | F18: =MSFT!F28+GOOGL!F28+AMZN!F28+META!F28 -> 110 | G18: =MSFT!G28+GOOGL!G28+AMZN!G28+META!G28 -> 105 | H18: =SUM(C18:G18) -> 640
A19: 주주환원 | B19: =MSFT!B31+GOOGL!B31+AMZN!B31+META!B31 -> 0 | C19: =MSFT!C31+GOOGL!C31+AMZN!C31+META!C31 -> 60.5 | D19: =MSFT!D31+GOOGL!D31+AMZN!D31+META!D31 -> 63 | E19: =MSFT!E31+GOOGL!E31+AMZN!E31+META!E31 -> 69 | F19: =MSFT!F31+GOOGL!F31+AMZN!F31+META!F31 -> 76 | G19: =MSFT!G31+GOOGL!G31+AMZN!G31+META!G31 -> 83 | H19: =SUM(C19:G19) -> 351.5
A20: FCF (OCF − 현금 capex) | B20: =MSFT!B38+GOOGL!B38+AMZN!B38+META!B38 -> 177.22 | C20: =MSFT!C38+GOOGL!C38+AMZN!C38+META!C38 -> -13.2984 | D20: =MSFT!D38+GOOGL!D38+AMZN!D38+META!D38 -> -53.282799 | E20: =MSFT!E38+GOOGL!E38+AMZN!E38+META!E38 -> -67.391001 | F20: =MSFT!F38+GOOGL!F38+AMZN!F38+META!F38 -> -59.748216 | G20: =MSFT!G38+GOOGL!G38+AMZN!G38+META!G38 -> -18.537839 | H20: =SUM(C20:G20) -> -212.25826
A21: 기말 현금 합계 | B21: =MSFT!B36+GOOGL!B36+AMZN!B36+META!B36 -> 0 | C21: =MSFT!C36+GOOGL!C36+AMZN!C36+META!C36 -> 613.8766 | D21: =MSFT!D36+GOOGL!D36+AMZN!D36+META!D36 -> 679.05128 | E21: =MSFT!E36+GOOGL!E36+AMZN!E36+META!E36 -> 763.12344 | F21: =MSFT!F36+GOOGL!F36+AMZN!F36+META!F36 -> 831.83039 | G21: =MSFT!G36+GOOGL!G36+AMZN!G36+META!G36 -> 925.93846 | H21: =G21 -> 925.93846
A22: 추가 조달 필요액 | B22: =MSFT!B35+GOOGL!B35+AMZN!B35+META!B35 -> 0 | C22: =MSFT!C35+GOOGL!C35+AMZN!C35+META!C35 -> 0 | D22: =MSFT!D35+GOOGL!D35+AMZN!D35+META!D35 -> 0.85935 | E22: =MSFT!E35+GOOGL!E35+AMZN!E35+META!E35 -> 29.65036 | F22: =MSFT!F35+GOOGL!F35+AMZN!F35+META!F35 -> 28.282602 | G22: =MSFT!G35+GOOGL!G35+AMZN!G35+META!G35 -> 18.16473 | H22: =SUM(C22:G22) -> 76.957041
A23: 총부채 (온밸런스) | B23: =MSFT!B39+GOOGL!B39+AMZN!B39+META!B39 -> 356 | C23: =MSFT!C39+GOOGL!C39+AMZN!C39+META!C39 -> 485 | D23: =MSFT!D39+GOOGL!D39+AMZN!D39+META!D39 -> 600.85935 | E23: =MSFT!E39+GOOGL!E39+AMZN!E39+META!E39 -> 740.50971 | F23: =MSFT!F39+GOOGL!F39+AMZN!F39+META!F39 -> 853.79231 | G23: =MSFT!G39+GOOGL!G39+AMZN!G39+META!G39 -> 951.95704 | H23: =G23 -> 951.95704
A24: 누적 리스/JV 잔액 | B24: =MSFT!B40+GOOGL!B40+AMZN!B40+META!B40 -> 0 | C24: =MSFT!C40+GOOGL!C40+AMZN!C40+META!C40 -> 71.675 | D24: =MSFT!D40+GOOGL!D40+AMZN!D40+META!D40 -> 172.27312 | E24: =MSFT!E40+GOOGL!E40+AMZN!E40+META!E40 -> 288.08593 | F24: =MSFT!F40+GOOGL!F40+AMZN!F40+META!F40 -> 414.25849 | G24: =MSFT!G40+GOOGL!G40+AMZN!G40+META!G40 -> 546.73968 | H24: =G24 -> 546.73968
A26: 회사별 Capex ($B)
A27: MSFT | B27: =MSFT!B14 -> 118 | C27: =MSFT!C14 -> 175 | D27: =MSFT!D14 -> 218.75 | E27: =MSFT!E14 -> 251.5625 | F27: =MSFT!F14 -> 276.71875 | G27: =MSFT!G14 -> 290.55469 | H27: =SUM(C27:G27) -> 1212.5859
A28: GOOGL | B28: =GOOGL!B14 -> 91 | C28: =GOOGL!C14 -> 200 | D28: =GOOGL!D14 -> 260 | E28: =GOOGL!E14 -> 299 | F28: =GOOGL!F14 -> 328.9 | G28: =GOOGL!G14 -> 345.345 | H28: =SUM(C28:G28) -> 1433.245
A29: AMZN | B29: =AMZN!B14 -> 131 | C29: =AMZN!C14 -> 220 | D29: =AMZN!D14 -> 264 | E29: =AMZN!E14 -> 295.68 | F29: =AMZN!F14 -> 319.3344 | G29: =AMZN!G14 -> 335.30112 | H29: =SUM(C29:G29) -> 1434.3155
A30: META | B30: =META!B14 -> 72 | C30: =META!C14 -> 137.5 | D30: =META!D14 -> 165 | E30: =META!E14 -> 184.8 | F30: =META!F14 -> 199.584 | G30: =META!G14 -> 209.5632 | H30: =SUM(C30:G30) -> 896.4472
A32: 회사별 Capex 비중
A33: MSFT | B33: =IF(B$6=0,0,B27/B$6) -> 0.28640777 | C33: =IF(C$6=0,0,C27/C$6) -> 0.23890785 | D33: =IF(D$6=0,0,D27/D$6) -> 0.24098045 | E33: =IF(E$6=0,0,E27/E$6) -> 0.24398849 | F33: =IF(F$6=0,0,F27/F$6) -> 0.24607346 | G33: =IF(G$6=0,0,G27/G$6) -> 0.24607346 | H33: =IF(H$6=0,0,H27/H$6) -> 0.24365782
A34: GOOGL | B34: =IF(B$6=0,0,B28/B$6) -> 0.22087379 | C34: =IF(C$6=0,0,C28/C$6) -> 0.27303754 | D34: =IF(D$6=0,0,D28/D$6) -> 0.28642247 | E34: =IF(E$6=0,0,E28/E$6) -> 0.28999775 | F34: =IF(F$6=0,0,F28/F$6) -> 0.29247589 | G34: =IF(G$6=0,0,G28/G$6) -> 0.29247589 | H34: =IF(H$6=0,0,H28/H$6) -> 0.28799719
A35: AMZN | B35: =IF(B$6=0,0,B29/B$6) -> 0.31796117 | C35: =IF(C$6=0,0,C29/C$6) -> 0.3003413 | D35: =IF(D$6=0,0,D29/D$6) -> 0.29082897 | E35: =IF(E$6=0,0,E29/E$6) -> 0.2867777 | F35: =IF(F$6=0,0,F29/F$6) -> 0.28396963 | G35: =IF(G$6=0,0,G29/G$6) -> 0.28396963 | H35: =IF(H$6=0,0,H29/H$6) -> 0.2882123
A36: META | B36: =IF(B$6=0,0,B30/B$6) -> 0.17475728 | C36: =IF(C$6=0,0,C30/C$6) -> 0.18771331 | D36: =IF(D$6=0,0,D30/D$6) -> 0.18176811 | E36: =IF(E$6=0,0,E30/E$6) -> 0.17923606 | F36: =IF(F$6=0,0,F30/F$6) -> 0.17748102 | G36: =IF(G$6=0,0,G30/G$6) -> 0.17748102 | H36: =IF(H$6=0,0,H30/H$6) -> 0.18013269
A38: 회사별 추가 조달 필요액 ($B)
A39: MSFT | B39: =MSFT!B35 -> 0 | C39: =MSFT!C35 -> 0 | D39: =MSFT!D35 -> 0.85935 | E39: =MSFT!E35 -> 29.65036 | F39: =MSFT!F35 -> 28.282602 | G39: =MSFT!G35 -> 18.16473 | H39: =SUM(C39:G39) -> 76.957041
A40: GOOGL | B40: =GOOGL!B35 -> 0 | C40: =GOOGL!C35 -> 0 | D40: =GOOGL!D35 -> 0 | E40: =GOOGL!E35 -> 0 | F40: =GOOGL!F35 -> 0 | G40: =GOOGL!G35 -> 0 | H40: =SUM(C40:G40) -> 0
A41: AMZN | B41: =AMZN!B35 -> 0 | C41: =AMZN!C35 -> 0 | D41: =AMZN!D35 -> 0 | E41: =AMZN!E35 -> 0 | F41: =AMZN!F35 -> 0 | G41: =AMZN!G35 -> 0 | H41: =SUM(C41:G41) -> 0
A42: META | B42: =META!B35 -> 0 | C42: =META!C35 -> 0 | D42: =META!D35 -> 0 | E42: =META!E35 -> 0 | F42: =META!F35 -> 0 | G42: =META!G35 -> 0 | H42: =SUM(C42:G42) -> 0

Sheet Sheet

Sheet MSFT
A1: Microsoft (MSFT) — Capex & 자금조달 ($B)
A2: 회계연도 6월 결산 → 달력연도(CY)로 환산. 2026E $175B는 FY27부터 DC 내용연수 15→25년 변경으로 금융리스→운용리스 재분류 반영(경제적 투자액은 ~$190B 유지). Capex에 금융리스 포함.
A3: 출처: Microsoft FY26 Q4 earnings call (2026-07-29): Q4 capex $41B, 2/3 short-lived assets, CY2026 capex ≈$175B(리스 재분류 후), FY27 capex YoY 증가, FY26 주주환원 $43B+, FY26 매출 $331B
A5: 항목 | B5: 2025A | C5: 2026E | D5: 2027E | E5: 2028E | F5: 2029E | G5: 2030E | H5: 메모
A6: 매출 · 영업현금흐름
A7: 매출 성장률 | C7: 0.16 | D7: 0.14 | E7: 0.12 | F7: 0.11 | G7: 0.1
A8: 매출 ($B) | B8: 305 | C8: =B8*(1+C7) -> 353.8 | D8: =C8*(1+D7) -> 403.332 | E8: =D8*(1+E7) -> 451.73184 | F8: =E8*(1+F7) -> 501.42234 | G8: =F8*(1+G7) -> 551.56458 | H8: 2025A는 추정치 — 10-K 확인 필요
A9: OCF 마진 | B9: 0.45 | C9: 0.45 | D9: 0.45 | E9: 0.45 | F9: 0.45 | G9: 0.45
A10: 영업현금흐름 OCF ($B) | B10: =B8*B9 -> 137.25 | C10: =C8*C9 -> 159.21 | D10: =D8*D9 -> 181.4994 | E10: =E8*E9 -> 203.27933 | F10: =F8*F9 -> 225.64005 | G10: =G8*G9 -> 248.20406
A12: Capex
A13: Capex 성장률 (2027E~) | D13: =D44+Scenario!D11 -> 0.25 | E13: =E44+Scenario!E11 -> 0.15 | F13: =F44+Scenario!F11 -> 0.1 | G13: =G44+Scenario!G11 -> 0.05 | H13: 44행 기본값 + Scenario 조정(%p)
A14: 총 Capex ($B) | B14: 118 | C14: 175 | D14: =C14*(1+D13) -> 218.75 | E14: =D14*(1+E13) -> 251.5625 | F14: =E14*(1+F13) -> 276.71875 | G14: =F14*(1+G13) -> 290.55469 | H14: 2025A 실적(근사), 2026E 회사 가이던스 중간값
A15: Capex YoY | C15: =IF(B14=0,0,C14/B14-1) -> 0.48305085 | D15: =IF(C14=0,0,D14/C14-1) -> 0.25 | E15: =IF(D14=0,0,E14/D14-1) -> 0.15 | F15: =IF(E14=0,0,F14/E14-1) -> 0.1 | G15: =IF(F14=0,0,G14/F14-1) -> 0.05
A16: Capex / 매출 | B16: =IF(B8=0,0,B14/B8) -> 0.38688525 | C16: =IF(C8=0,0,C14/C8) -> 0.49462973 | D16: =IF(D8=0,0,D14/D8) -> 0.54235716 | E16: =IF(E8=0,0,E14/E8) -> 0.55688459 | F16: =IF(F8=0,0,F14/F8) -> 0.55186761 | G16: =IF(G8=0,0,G14/G8) -> 0.52678272
A17: Capex / OCF | B17: =IF(B10=0,0,B14/B10) -> 0.85974499 | C17: =IF(C10=0,0,C14/C10) -> 1.0991772 | D17: =IF(D10=0,0,D14/D10) -> 1.2052381 | E17: =IF(E10=0,0,E14/E10) -> 1.2375213 | F17: =IF(F10=0,0,F14/F10) -> 1.2263725 | G17: =IF(G10=0,0,G14/G10) -> 1.1706283
A18: 서버·칩(단기자산) 비중 | B18: 0.6 | C18: 0.67 | D18: 0.67 | E18: 0.65 | F18: 0.65 | G18: 0.65 | H18: GPU/CPU/메모리 등 3~6년 자산. 나머지는 DC·전력·네트워크(장기자산)
A19: 서버·칩 capex ($B) | B19: =B14*B18 -> 70.8 | C19: =C14*C18 -> 117.25 | D19: =D14*D18 -> 146.5625 | E19: =E14*E18 -> 163.51562 | F19: =F14*F18 -> 179.86719 | G19: =G14*G18 -> 188.86055
A20: DC·전력·네트워크 capex ($B) | B20: =B14-B19 -> 47.2 | C20: =C14-C19 -> 57.75 | D20: =D14-D19 -> 72.1875 | E20: =E14-E19 -> 88.046875 | F20: =F14-F19 -> 96.851562 | G20: =G14-G19 -> 101.69414
A21: DC capex 중 리스/JV 조달 비율 | B21: 0.25 | C21: 0.3 | D21: 0.35 | E21: 0.35 | F21: 0.35 | G21: 0.35 | H21: 오프밸런스·파트너 자본(JV, 빌드투수트 리스, 사모채)
A22: 리스/JV 조달액 ($B) | B22: =B20*B21 -> 11.8 | C22: =C20*C21 -> 17.325 | D22: =D20*D21 -> 25.265625 | E22: =E20*E21 -> 30.816406 | F22: =F20*F21 -> 33.898047 | G22: =G20*G21 -> 35.592949
A23: 현금 지출 capex ($B) | B23: =B14-B22 -> 106.2 | C23: =C14-C22 -> 157.675 | D23: =D14-D22 -> 193.48438 | E23: =E14-E22 -> 220.74609 | F23: =F14-F22 -> 242.8207 | G23: =G14-G22 -> 254.96174
A25: 자금조달 (Sources & Uses)
A26: 기초 현금 ($B) | B26: 95 | C26: =B26 -> 95 | D26: =C36 -> 65.86 | E26: =D36 -> 40 | F26: =E36 -> 40 | G26: =F36 -> 40 | H26: 2025년말 현금·유가증권 (근사)
A27: (+) OCF | C27: =C10 -> 159.21 | D27: =D10 -> 181.4994 | E27: =E10 -> 203.27933 | F27: =F10 -> 225.64005 | G27: =G10 -> 248.20406
A28: (+) 신규 부채 발행 | C28: 10 | D28: 20 | E28: 20 | F28: 20 | G28: 20 | H28: 회사채·은행차입 가정 (입력)
A29: (+) 리스/JV 조달 | C29: =C22 -> 17.325 | D29: =D22 -> 25.265625 | E29: =E22 -> 30.816406 | F29: =F22 -> 33.898047 | G29: =G22 -> 35.592949
A30: (−) 현금 capex | C30: =C23 -> 157.675 | D30: =D23 -> 193.48438 | E30: =E23 -> 220.74609 | F30: =F23 -> 242.8207 | G30: =G23 -> 254.96174
A31: (−) 주주환원 (배당+자사주) | C31: 43 | D31: 45 | E31: 48 | F31: 50 | G31: 52
A32: (−) 부채 상환 · 기타 투자 | C32: 15 | D32: 15 | E32: 15 | F32: 15 | G32: 15 | H32: 부채 상환 + M&A/전략투자 등 가정 (입력)
A33: 조달 전 기말 현금 ($B) | C33: =C26+C27+C28+C29-C30-C31-C32 -> 65.86 | D33: =D26+D27+D28+D29-D30-D31-D32 -> 39.14065 | E33: =E26+E27+E28+E29-E30-E31-E32 -> 10.349641 | F33: =F26+F27+F28+F29-F30-F31-F32 -> 11.717398 | G33: =G26+G27+G28+G29-G30-G31-G32 -> 21.83527
A34: 최소 유지 현금 | B34: 40 | C34: =$B$34 -> 40 | D34: =$B$34 -> 40 | E34: =$B$34 -> 40 | F34: =$B$34 -> 40 | G34: =$B$34 -> 40
A35: 추가 조달 필요액 — 플러그 ($B) | C35: =MAX(0,C34-C33) -> 0 | D35: =MAX(0,D34-D33) -> 0.85935 | E35: =MAX(0,E34-E33) -> 29.65036 | F35: =MAX(0,F34-F33) -> 28.282602 | G35: =MAX(0,G34-G33) -> 18.16473 | H35: 조달 전 현금이 최소치 미만이면 부족분을 자동 조달(부채 가정)해 기말현금에 가산. 총부채에도 반영
A36: 기말 현금 ($B) | C36: =C33+C35 -> 65.86 | D36: =D33+D35 -> 40 | E36: =E33+E35 -> 40 | F36: =F33+F35 -> 40 | G36: =G33+G35 -> 40
A37: 지표
A38: FCF (OCF − 현금 capex) | B38: =B10-B23 -> 31.05 | C38: =C10-C23 -> 1.535 | D38: =D10-D23 -> -11.984975 | E38: =E10-E23 -> -17.466766 | F38: =F10-F23 -> -17.180649 | G38: =G10-G23 -> -6.7576788
A39: 총부채 (온밸런스, $B) | B39: 45 | C39: =B39+C28+C35-5 -> 50 | D39: =C39+D28+D35-5 -> 65.85935 | E39: =D39+E28+E35-5 -> 110.50971 | F39: =E39+F28+F35-5 -> 153.79231 | G39: =F39+G28+G35-5 -> 186.95704 | H39: 2025A 입력; 이후 = 전기 + 발행 + 플러그 − 상환(상환액 고정: 5,5,5,5,5)
A40: 누적 리스/JV 잔액 ($B) | B40: 0 | C40: =B40+C29 -> 17.325 | D40: =C40+D29 -> 42.590625 | E40: =D40+E29 -> 73.407031 | F40: =E40+F29 -> 107.30508 | G40: =F40+G29 -> 142.89803
A41: 총부채 / OCF | B41: =IF(B10=0,0,B39/B10) -> 0.32786885 | C41: =IF(C10=0,0,C39/C10) -> 0.31405062 | D41: =IF(D10=0,0,D39/D10) -> 0.36286263 | E41: =IF(E10=0,0,E39/E10) -> 0.54363476 | F41: =IF(F10=0,0,F39/F10) -> 0.6815825 | G41: =IF(G10=0,0,G39/G10) -> 0.75323926
A42: (총부채+리스/JV) / OCF | B42: =IF(B10=0,0,(B39+B40)/B10) -> 0.32786885 | C42: =IF(C10=0,0,(C39+C40)/C10) -> 0.42286917 | D42: =IF(D10=0,0,(D39+D40)/D10) -> 0.5975225 | E42: =IF(E10=0,0,(E39+E40)/E10) -> 0.90474886 | F42: =IF(F10=0,0,(F39+F40)/F10) -> 1.1571411 | G42: =IF(G10=0,0,(G39+G40)/G10) -> 1.3289673
A44: Capex 성장률 기본값 (Base 입력) | D44: 0.25 | E44: 0.15 | F44: 0.1 | G44: 0.05 | H44: 2027E~ capex 성장률 기본 가정 (시나리오 조정은 Scenario 시트)

Sheet GOOGL
A1: Alphabet (GOOGL) — Capex & 자금조달 ($B)
A2: 12월 결산. Capex = 현금 PP&E 기준(리스 미포함). 2026 가이던스 $195~205B 중간값 사용. 2027은 'significantly increase' 코멘트만 있어 성장률 가정.
A3: 출처: Alphabet Q2 2026 earnings call (2026-07-22): 2026 capex $195~205B(종전 180~190), Q2 capex $44.9B 중 ~60% 서버/40% DC·네트워크, 2027 capex 큰 폭 증가 예정, 현금·유가증권 $242.5B, 장기부채 $98.2B, Q2 FCF -$5.9B
A5: 항목 | B5: 2025A | C5: 2026E | D5: 2027E | E5: 2028E | F5: 2029E | G5: 2030E | H5: 메모
A6: 매출 · 영업현금흐름
A7: 매출 성장률 | C7: 0.22 | D7: 0.16 | E7: 0.13 | F7: 0.11 | G7: 0.1
A8: 매출 ($B) | B8: 402 | C8: =B8*(1+C7) -> 490.44 | D8: =C8*(1+D7) -> 568.9104 | E8: =D8*(1+E7) -> 642.86875 | F8: =E8*(1+F7) -> 713.58431 | G8: =F8*(1+G7) -> 784.94275 | H8: 2025A는 추정치 — 10-K 확인 필요
A9: OCF 마진 | B9: 0.38 | C9: 0.36 | D9: 0.36 | E9: 0.36 | F9: 0.36 | G9: 0.36
A10: 영업현금흐름 OCF ($B) | B10: =B8*B9 -> 152.76 | C10: =C8*C9 -> 176.5584 | D10: =D8*D9 -> 204.80774 | E10: =E8*E9 -> 231.43275 | F10: =F8*F9 -> 256.89035 | G10: =G8*G9 -> 282.57939
A12: Capex
A13: Capex 성장률 (2027E~) | D13: =D44+Scenario!D11 -> 0.3 | E13: =E44+Scenario!E11 -> 0.15 | F13: =F44+Scenario!F11 -> 0.1 | G13: =G44+Scenario!G11 -> 0.05 | H13: 44행 기본값 + Scenario 조정(%p)
A14: 총 Capex ($B) | B14: 91 | C14: 200 | D14: =C14*(1+D13) -> 260 | E14: =D14*(1+E13) -> 299 | F14: =E14*(1+F13) -> 328.9 | G14: =F14*(1+G13) -> 345.345 | H14: 2025A 실적(근사), 2026E 회사 가이던스 중간값
A15: Capex YoY | C15: =IF(B14=0,0,C14/B14-1) -> 1.1978022 | D15: =IF(C14=0,0,D14/C14-1) -> 0.3 | E15: =IF(D14=0,0,E14/D14-1) -> 0.15 | F15: =IF(E14=0,0,F14/E14-1) -> 0.1 | G15: =IF(F14=0,0,G14/F14-1) -> 0.05
A16: Capex / 매출 | B16: =IF(B8=0,0,B14/B8) -> 0.22636816 | C16: =IF(C8=0,0,C14/C8) -> 0.40779708 | D16: =IF(D8=0,0,D14/D8) -> 0.45701397 | E16: =IF(E8=0,0,E14/E8) -> 0.46510271 | F16: =IF(F8=0,0,F14/F8) -> 0.4609126 | G16: =IF(G8=0,0,G14/G8) -> 0.43996202
A17: Capex / OCF | B17: =IF(B10=0,0,B14/B10) -> 0.59570568 | C17: =IF(C10=0,0,C14/C10) -> 1.1327697 | D17: =IF(D10=0,0,D14/D10) -> 1.2694832 | E17: =IF(E10=0,0,E14/E10) -> 1.291952 | F17: =IF(F10=0,0,F14/F10) -> 1.2803128 | G17: =IF(G10=0,0,G14/G10) -> 1.2221167
A18: 서버·칩(단기자산) 비중 | B18: 0.6 | C18: 0.6 | D18: 0.6 | E18: 0.6 | F18: 0.6 | G18: 0.6 | H18: GPU/CPU/메모리 등 3~6년 자산. 나머지는 DC·전력·네트워크(장기자산)
A19: 서버·칩 capex ($B) | B19: =B14*B18 -> 54.6 | C19: =C14*C18 -> 120 | D19: =D14*D18 -> 156 | E19: =E14*E18 -> 179.4 | F19: =F14*F18 -> 197.34 | G19: =G14*G18 -> 207.207
A20: DC·전력·네트워크 capex ($B) | B20: =B14-B19 -> 36.4 | C20: =C14-C19 -> 80 | D20: =D14-D19 -> 104 | E20: =E14-E19 -> 119.6 | F20: =F14-F19 -> 131.56 | G20: =G14-G19 -> 138.138
A21: DC capex 중 리스/JV 조달 비율 | B21: 0.1 | C21: 0.15 | D21: 0.2 | E21: 0.2 | F21: 0.2 | G21: 0.2 | H21: 오프밸런스·파트너 자본(JV, 빌드투수트 리스, 사모채)
A22: 리스/JV 조달액 ($B) | B22: =B20*B21 -> 3.64 | C22: =C20*C21 -> 12 | D22: =D20*D21 -> 20.8 | E22: =E20*E21 -> 23.92 | F22: =F20*F21 -> 26.312 | G22: =G20*G21 -> 27.6276
A23: 현금 지출 capex ($B) | B23: =B14-B22 -> 87.36 | C23: =C14-C22 -> 188 | D23: =D14-D22 -> 239.2 | E23: =E14-E22 -> 275.08 | F23: =F14-F22 -> 302.588 | G23: =G14-G22 -> 317.7174
A25: 자금조달 (Sources & Uses)
A26: 기초 현금 ($B) | B26: 242 | C26: =B26 -> 242 | D26: =C36 -> 245.5584 | E26: =D36 -> 244.96614 | F26: =E36 -> 235.23889 | G26: =F36 -> 210.85325 | H26: 2025년말 현금·유가증권 (근사)
A27: (+) OCF | C27: =C10 -> 176.5584 | D27: =D10 -> 204.80774 | E27: =E10 -> 231.43275 | F27: =F10 -> 256.89035 | G27: =G10 -> 282.57939
A28: (+) 신규 부채 발행 | C28: 30 | D28: 40 | E28: 40 | F28: 30 | G28: 30 | H28: 회사채·은행차입 가정 (입력)
A29: (+) 리스/JV 조달 | C29: =C22 -> 12 | D29: =D22 -> 20.8 | E29: =E22 -> 23.92 | F29: =F22 -> 26.312 | G29: =G22 -> 27.6276
A30: (−) 현금 capex | C30: =C23 -> 188 | D30: =D23 -> 239.2 | E30: =E23 -> 275.08 | F30: =F23 -> 302.588 | G30: =G23 -> 317.7174
A31: (−) 주주환원 (배당+자사주) | C31: 12 | D31: 12 | E31: 15 | F31: 20 | G31: 25
A32: (−) 부채 상환 · 기타 투자 | C32: 15 | D32: 15 | E32: 15 | F32: 15 | G32: 15 | H32: 부채 상환 + M&A/전략투자 등 가정 (입력)
A33: 조달 전 기말 현금 ($B) | C33: =C26+C27+C28+C29-C30-C31-C32 -> 245.5584 | D33: =D26+D27+D28+D29-D30-D31-D32 -> 244.96614 | E33: =E26+E27+E28+E29-E30-E31-E32 -> 235.23889 | F33: =F26+F27+F28+F29-F30-F31-F32 -> 210.85325 | G33: =G26+G27+G28+G29-G30-G31-G32 -> 193.34284
A34: 최소 유지 현금 | B34: 60 | C34: =$B$34 -> 60 | D34: =$B$34 -> 60 | E34: =$B$34 -> 60 | F34: =$B$34 -> 60 | G34: =$B$34 -> 60
A35: 추가 조달 필요액 — 플러그 ($B) | C35: =MAX(0,C34-C33) -> 0 | D35: =MAX(0,D34-D33) -> 0 | E35: =MAX(0,E34-E33) -> 0 | F35: =MAX(0,F34-F33) -> 0 | G35: =MAX(0,G34-G33) -> 0 | H35: 조달 전 현금이 최소치 미만이면 부족분을 자동 조달(부채 가정)해 기말현금에 가산. 총부채에도 반영
A36: 기말 현금 ($B) | C36: =C33+C35 -> 245.5584 | D36: =D33+D35 -> 244.96614 | E36: =E33+E35 -> 235.23889 | F36: =F33+F35 -> 210.85325 | G36: =G33+G35 -> 193.34284
A37: 지표
A38: FCF (OCF − 현금 capex) | B38: =B10-B23 -> 65.4 | C38: =C10-C23 -> -11.4416 | D38: =D10-D23 -> -34.392256 | E38: =E10-E23 -> -43.647249 | F38: =F10-F23 -> -45.697647 | G38: =G10-G23 -> -35.138011
A39: 총부채 (온밸런스, $B) | B39: 98 | C39: =B39+C28+C35-5 -> 123 | D39: =C39+D28+D35-5 -> 158 | E39: =D39+E28+E35-5 -> 193 | F39: =E39+F28+F35-5 -> 218 | G39: =F39+G28+G35-5 -> 243 | H39: 2025A 입력; 이후 = 전기 + 발행 + 플러그 − 상환(상환액 고정: 5,5,5,5,5)
A40: 누적 리스/JV 잔액 ($B) | B40: 0 | C40: =B40+C29 -> 12 | D40: =C40+D29 -> 32.8 | E40: =D40+E29 -> 56.72 | F40: =E40+F29 -> 83.032 | G40: =F40+G29 -> 110.6596
A41: 총부채 / OCF | B41: =IF(B10=0,0,B39/B10) -> 0.6415292 | C41: =IF(C10=0,0,C39/C10) -> 0.69665335 | D41: =IF(D10=0,0,D39/D10) -> 0.7714552 | E41: =IF(E10=0,0,E39/E10) -> 0.83393556 | F41: =IF(F10=0,0,F39/F10) -> 0.84861108 | G41: =IF(G10=0,0,G39/G10) -> 0.85993533
A42: (총부채+리스/JV) / OCF | B42: =IF(B10=0,0,(B39+B40)/B10) -> 0.6415292 | C42: =IF(C10=0,0,(C39+C40)/C10) -> 0.76461953 | D42: =IF(D10=0,0,(D39+D40)/D10) -> 0.9316054 | E42: =IF(E10=0,0,(E39+E40)/E10) -> 1.0790176 | F42: =IF(F10=0,0,(F39+F40)/F10) -> 1.1718307 | G42: =IF(G10=0,0,(G39+G40)/G10) -> 1.2515407
A44: Capex 성장률 기본값 (Base 입력) | D44: 0.3 | E44: 0.15 | F44: 0.1 | G44: 0.05 | H44: 2027E~ capex 성장률 기본 가정 (시나리오 조정은 Scenario 시트)

Sheet AMZN
A1: Amazon (AMZN) — Capex & 자금조달 ($B)
A2: 12월 결산. Capex = 현금 capex 기준(금융리스 별도). 리테일·물류 capex 포함 총액이므로 AI/AWS 비중 가정 필요. 2026 $220B 중 ~$20B는 메모리 가격 상승분(용량 증가 없음).
A3: 출처: Amazon Q2 2026 earnings call (2026-07-30): 2026 현금 capex ≈$220B(종전 ~$200B, 메모리 가격 상승), Q2 capex $53.1B, TTM FCF -$7.6B, TTM capex $169B, 장기부채 $128.9B(6개월간 ~2배), AWS 백로그 $496B
A5: 항목 | B5: 2025A | C5: 2026E | D5: 2027E | E5: 2028E | F5: 2029E | G5: 2030E | H5: 메모
A6: 매출 · 영업현금흐름
A7: 매출 성장률 | C7: 0.18 | D7: 0.14 | E7: 0.12 | F7: 0.1 | G7: 0.09
A8: 매출 ($B) | B8: 717 | C8: =B8*(1+C7) -> 846.06 | D8: =C8*(1+D7) -> 964.5084 | E8: =D8*(1+E7) -> 1080.2494 | F8: =E8*(1+F7) -> 1188.2743 | G8: =F8*(1+G7) -> 1295.219 | H8: 2025A는 추정치 — 10-K 확인 필요
A9: OCF 마진 | B9: 0.22 | C9: 0.22 | D9: 0.23 | E9: 0.23 | F9: 0.23 | G9: 0.23
A10: 영업현금흐름 OCF ($B) | B10: =B8*B9 -> 157.74 | C10: =C8*C9 -> 186.1332 | D10: =D8*D9 -> 221.83693 | E10: =E8*E9 -> 248.45736 | F10: =F8*F9 -> 273.3031 | G10: =G8*G9 -> 297.90038
A12: Capex
A13: Capex 성장률 (2027E~) | D13: =D44+Scenario!D11 -> 0.2 | E13: =E44+Scenario!E11 -> 0.12 | F13: =F44+Scenario!F11 -> 0.08 | G13: =G44+Scenario!G11 -> 0.05 | H13: 44행 기본값 + Scenario 조정(%p)
A14: 총 Capex ($B) | B14: 131 | C14: 220 | D14: =C14*(1+D13) -> 264 | E14: =D14*(1+E13) -> 295.68 | F14: =E14*(1+F13) -> 319.3344 | G14: =F14*(1+G13) -> 335.30112 | H14: 2025A 실적(근사), 2026E 회사 가이던스 중간값
A15: Capex YoY | C15: =IF(B14=0,0,C14/B14-1) -> 0.67938931 | D15: =IF(C14=0,0,D14/C14-1) -> 0.2 | E15: =IF(D14=0,0,E14/D14-1) -> 0.12 | F15: =IF(E14=0,0,F14/E14-1) -> 0.08 | G15: =IF(F14=0,0,G14/F14-1) -> 0.05
A16: Capex / 매출 | B16: =IF(B8=0,0,B14/B8) -> 0.18270572 | C16: =IF(C8=0,0,C14/C8) -> 0.26002884 | D16: =IF(D8=0,0,D14/D8) -> 0.27371457 | E16: =IF(E8=0,0,E14/E8) -> 0.27371457 | F16: =IF(F8=0,0,F14/F8) -> 0.26873794 | G16: =IF(G8=0,0,G14/G8) -> 0.258876
A17: Capex / OCF | B17: =IF(B10=0,0,B14/B10) -> 0.83048054 | C17: =IF(C10=0,0,C14/C10) -> 1.1819493 | D17: =IF(D10=0,0,D14/D10) -> 1.1900633 | E17: =IF(E10=0,0,E14/E10) -> 1.1900633 | F17: =IF(F10=0,0,F14/F10) -> 1.1684258 | G17: =IF(G10=0,0,G14/G10) -> 1.1255478
A18: 서버·칩(단기자산) 비중 | B18: 0.55 | C18: 0.6 | D18: 0.6 | E18: 0.6 | F18: 0.6 | G18: 0.6 | H18: GPU/CPU/메모리 등 3~6년 자산. 나머지는 DC·전력·네트워크(장기자산)
A19: 서버·칩 capex ($B) | B19: =B14*B18 -> 72.05 | C19: =C14*C18 -> 132 | D19: =D14*D18 -> 158.4 | E19: =E14*E18 -> 177.408 | F19: =F14*F18 -> 191.60064 | G19: =G14*G18 -> 201.18067
A20: DC·전력·네트워크 capex ($B) | B20: =B14-B19 -> 58.95 | C20: =C14-C19 -> 88 | D20: =D14-D19 -> 105.6 | E20: =E14-E19 -> 118.272 | F20: =F14-F19 -> 127.73376 | G20: =G14-G19 -> 134.12045
A21: DC capex 중 리스/JV 조달 비율 | B21: 0.2 | C21: 0.2 | D21: 0.2 | E21: 0.2 | F21: 0.2 | G21: 0.2 | H21: 오프밸런스·파트너 자본(JV, 빌드투수트 리스, 사모채)
A22: 리스/JV 조달액 ($B) | B22: =B20*B21 -> 11.79 | C22: =C20*C21 -> 17.6 | D22: =D20*D21 -> 21.12 | E22: =E20*E21 -> 23.6544 | F22: =F20*F21 -> 25.546752 | G22: =G20*G21 -> 26.82409
A23: 현금 지출 capex ($B) | B23: =B14-B22 -> 119.21 | C23: =C14-C22 -> 202.4 | D23: =D14-D22 -> 242.88 | E23: =E14-E22 -> 272.0256 | F23: =F14-F22 -> 293.78765 | G23: =G14-G22 -> 308.47703
A25: 자금조달 (Sources & Uses)
A26: 기초 현금 ($B) | B26: 95 | C26: =B26 -> 95 | D26: =C36 -> 143.3332 | E26: =D36 -> 163.41013 | F26: =E36 -> 183.4963 | G26: =F36 -> 198.5585 | H26: 2025년말 현금·유가증권 (근사)
A27: (+) OCF | C27: =C10 -> 186.1332 | D27: =D10 -> 221.83693 | E27: =E10 -> 248.45736 | F27: =F10 -> 273.3031 | G27: =G10 -> 297.90038
A28: (+) 신규 부채 발행 | C28: 65 | D28: 40 | E28: 40 | F28: 30 | G28: 30 | H28: 회사채·은행차입 가정 (입력)
A29: (+) 리스/JV 조달 | C29: =C22 -> 17.6 | D29: =D22 -> 21.12 | E29: =E22 -> 23.6544 | F29: =F22 -> 25.546752 | G29: =G22 -> 26.82409
A30: (−) 현금 capex | C30: =C23 -> 202.4 | D30: =D23 -> 242.88 | E30: =E23 -> 272.0256 | F30: =F23 -> 293.78765 | G30: =G23 -> 308.47703
A31: (−) 주주환원 (배당+자사주) | C31: 0 | D31: 0 | E31: 0 | F31: 0 | G31: 0
A32: (−) 부채 상환 · 기타 투자 | C32: 18 | D32: 20 | E32: 20 | F32: 20 | G32: 20 | H32: 부채 상환 + M&A/전략투자 등 가정 (입력)
A33: 조달 전 기말 현금 ($B) | C33: =C26+C27+C28+C29-C30-C31-C32 -> 143.3332 | D33: =D26+D27+D28+D29-D30-D31-D32 -> 163.41013 | E33: =E26+E27+E28+E29-E30-E31-E32 -> 183.4963 | F33: =F26+F27+F28+F29-F30-F31-F32 -> 198.5585 | G33: =G26+G27+G28+G29-G30-G31-G32 -> 224.80594
A34: 최소 유지 현금 | B34: 40 | C34: =$B$34 -> 40 | D34: =$B$34 -> 40 | E34: =$B$34 -> 40 | F34: =$B$34 -> 40 | G34: =$B$34 -> 40
A35: 추가 조달 필요액 — 플러그 ($B) | C35: =MAX(0,C34-C33) -> 0 | D35: =MAX(0,D34-D33) -> 0 | E35: =MAX(0,E34-E33) -> 0 | F35: =MAX(0,F34-F33) -> 0 | G35: =MAX(0,G34-G33) -> 0 | H35: 조달 전 현금이 최소치 미만이면 부족분을 자동 조달(부채 가정)해 기말현금에 가산. 총부채에도 반영
A36: 기말 현금 ($B) | C36: =C33+C35 -> 143.3332 | D36: =D33+D35 -> 163.41013 | E36: =E33+E35 -> 183.4963 | F36: =F33+F35 -> 198.5585 | G36: =G33+G35 -> 224.80594
A37: 지표
A38: FCF (OCF − 현금 capex) | B38: =B10-B23 -> 38.53 | C38: =C10-C23 -> -16.2668 | D38: =D10-D23 -> -21.043068 | E38: =E10-E23 -> -23.568236 | F38: =F10-F23 -> -20.484548 | G38: =G10-G23 -> -10.576651
A39: 총부채 (온밸런스, $B) | B39: 129 | C39: =B39+C28+C35-8 -> 186 | D39: =C39+D28+D35-10 -> 216 | E39: =D39+E28+E35-10 -> 246 | F39: =E39+F28+F35-10 -> 266 | G39: =F39+G28+G35-10 -> 286 | H39: 2025A 입력; 이후 = 전기 + 발행 + 플러그 − 상환(상환액 고정: 8,10,10,10,10)
A40: 누적 리스/JV 잔액 ($B) | B40: 0 | C40: =B40+C29 -> 17.6 | D40: =C40+D29 -> 38.72 | E40: =D40+E29 -> 62.3744 | F40: =E40+F29 -> 87.921152 | G40: =F40+G29 -> 114.74524
A41: 총부채 / OCF | B41: =IF(B10=0,0,B39/B10) -> 0.81780145 | C41: =IF(C10=0,0,C39/C10) -> 0.99928438 | D41: =IF(D10=0,0,D39/D10) -> 0.97368819 | E41: =IF(E10=0,0,E39/E10) -> 0.99010951 | F41: =IF(F10=0,0,F39/F10) -> 0.97327838 | G41: =IF(G10=0,0,G39/G10) -> 0.96005249
A42: (총부채+리스/JV) / OCF | B42: =IF(B10=0,0,(B39+B40)/B10) -> 0.81780145 | C42: =IF(C10=0,0,(C39+C40)/C10) -> 1.0938403 | D42: =IF(D10=0,0,(D39+D40)/D10) -> 1.1482308 | E42: =IF(E10=0,0,(E39+E40)/E10) -> 1.2411562 | F42: =IF(F10=0,0,(F39+F40)/F10) -> 1.2949767 | G42: =IF(G10=0,0,(G39+G40)/G10) -> 1.3452324
A44: Capex 성장률 기본값 (Base 입력) | D44: 0.2 | E44: 0.12 | F44: 0.08 | G44: 0.05 | H44: 2027E~ capex 성장률 기본 가정 (시나리오 조정은 Scenario 시트)

Sheet META
A1: Meta (META) — Capex & 자금조달 ($B)
A2: 12월 결산. Capex에 금융리스 원금상환 포함. 클라우드 매출 없이 광고 OCF로 조달 → 부채·JV(Hyperion/Blue Owl, El Paso/BlackRock 등) 의존도 최고. 자사주 매입 중단.
A3: 출처: Meta Q2 2026 earnings call (2026-07-29): 2026 capex $130~145B(금융리스 원금 포함), Q2 capex $31.1B vs OCF $31.9B(FCF $0.8B), 현금 $90.3B·부채 $83.7B, 상반기 순부채발행 $24.9B, El Paso $14B(BlackRock JV), Hyperion >$50B
A5: 항목 | B5: 2025A | C5: 2026E | D5: 2027E | E5: 2028E | F5: 2029E | G5: 2030E | H5: 메모
A6: 매출 · 영업현금흐름
A7: 매출 성장률 | C7: 0.25 | D7: 0.16 | E7: 0.13 | F7: 0.11 | G7: 0.1
A8: 매출 ($B) | B8: 201 | C8: =B8*(1+C7) -> 251.25 | D8: =C8*(1+D7) -> 291.45 | E8: =D8*(1+E7) -> 329.3385 | F8: =E8*(1+F7) -> 365.56574 | G8: =F8*(1+G7) -> 402.12231 | H8: 2025A는 추정치 — 10-K 확인 필요
A9: OCF 마진 | B9: 0.52 | C9: 0.5 | D9: 0.5 | E9: 0.5 | F9: 0.5 | G9: 0.5
A10: 영업현금흐름 OCF ($B) | B10: =B8*B9 -> 104.52 | C10: =C8*C9 -> 125.625 | D10: =D8*D9 -> 145.725 | E10: =E8*E9 -> 164.66925 | F10: =F8*F9 -> 182.78287 | G10: =G8*G9 -> 201.06115
A12: Capex
A13: Capex 성장률 (2027E~) | D13: =D44+Scenario!D11 -> 0.2 | E13: =E44+Scenario!E11 -> 0.12 | F13: =F44+Scenario!F11 -> 0.08 | G13: =G44+Scenario!G11 -> 0.05 | H13: 44행 기본값 + Scenario 조정(%p)
A14: 총 Capex ($B) | B14: 72 | C14: 137.5 | D14: =C14*(1+D13) -> 165 | E14: =D14*(1+E13) -> 184.8 | F14: =E14*(1+F13) -> 199.584 | G14: =F14*(1+G13) -> 209.5632 | H14: 2025A 실적(근사), 2026E 회사 가이던스 중간값
A15: Capex YoY | C15: =IF(B14=0,0,C14/B14-1) -> 0.90972222 | D15: =IF(C14=0,0,D14/C14-1) -> 0.2 | E15: =IF(D14=0,0,E14/D14-1) -> 0.12 | F15: =IF(E14=0,0,F14/E14-1) -> 0.08 | G15: =IF(F14=0,0,G14/F14-1) -> 0.05
A16: Capex / 매출 | B16: =IF(B8=0,0,B14/B8) -> 0.35820896 | C16: =IF(C8=0,0,C14/C8) -> 0.54726368 | D16: =IF(D8=0,0,D14/D8) -> 0.56613484 | E16: =IF(E8=0,0,E14/E8) -> 0.5611248 | F16: =IF(F8=0,0,F14/F8) -> 0.54595927 | G16: =IF(G8=0,0,G14/G8) -> 0.52114293
A17: Capex / OCF | B17: =IF(B10=0,0,B14/B10) -> 0.68886338 | C17: =IF(C10=0,0,C14/C10) -> 1.0945274 | D17: =IF(D10=0,0,D14/D10) -> 1.1322697 | E17: =IF(E10=0,0,E14/E10) -> 1.1222496 | F17: =IF(F10=0,0,F14/F10) -> 1.0919185 | G17: =IF(G10=0,0,G14/G10) -> 1.0422859
A18: 서버·칩(단기자산) 비중 | B18: 0.55 | C18: 0.55 | D18: 0.55 | E18: 0.55 | F18: 0.55 | G18: 0.55 | H18: GPU/CPU/메모리 등 3~6년 자산. 나머지는 DC·전력·네트워크(장기자산)
A19: 서버·칩 capex ($B) | B19: =B14*B18 -> 39.6 | C19: =C14*C18 -> 75.625 | D19: =D14*D18 -> 90.75 | E19: =E14*E18 -> 101.64 | F19: =F14*F18 -> 109.7712 | G19: =G14*G18 -> 115.25976
A20: DC·전력·네트워크 capex ($B) | B20: =B14-B19 -> 32.4 | C20: =C14-C19 -> 61.875 | D20: =D14-D19 -> 74.25 | E20: =E14-E19 -> 83.16 | F20: =F14-F19 -> 89.8128 | G20: =G14-G19 -> 94.30344
A21: DC capex 중 리스/JV 조달 비율 | B21: 0.3 | C21: 0.4 | D21: 0.45 | E21: 0.45 | F21: 0.45 | G21: 0.45 | H21: 오프밸런스·파트너 자본(JV, 빌드투수트 리스, 사모채)
A22: 리스/JV 조달액 ($B) | B22: =B20*B21 -> 9.72 | C22: =C20*C21 -> 24.75 | D22: =D20*D21 -> 33.4125 | E22: =E20*E21 -> 37.422 | F22: =F20*F21 -> 40.41576 | G22: =G20*G21 -> 42.436548
A23: 현금 지출 capex ($B) | B23: =B14-B22 -> 62.28 | C23: =C14-C22 -> 112.75 | D23: =D14-D22 -> 131.5875 | E23: =E14-E22 -> 147.378 | F23: =F14-F22 -> 159.16824 | G23: =G14-G22 -> 167.12665
A25: 자금조달 (Sources & Uses)
A26: 기초 현금 ($B) | B26: 90 | C26: =B26 -> 90 | D26: =C36 -> 159.125 | E26: =D36 -> 230.675 | F26: =E36 -> 304.38825 | G26: =F36 -> 382.41864 | H26: 2025년말 현금·유가증권 (근사)
A27: (+) OCF | C27: =C10 -> 125.625 | D27: =D10 -> 145.725 | E27: =E10 -> 164.66925 | F27: =F10 -> 182.78287 | G27: =G10 -> 201.06115
A28: (+) 신규 부채 발행 | C28: 45 | D28: 40 | E28: 35 | F28: 30 | G28: 25 | H28: 회사채·은행차입 가정 (입력)
A29: (+) 리스/JV 조달 | C29: =C22 -> 24.75 | D29: =D22 -> 33.4125 | E29: =E22 -> 37.422 | F29: =F22 -> 40.41576 | G29: =G22 -> 42.436548
A30: (−) 현금 capex | C30: =C23 -> 112.75 | D30: =D23 -> 131.5875 | E30: =E23 -> 147.378 | F30: =F23 -> 159.16824 | G30: =G23 -> 167.12665
A31: (−) 주주환원 (배당+자사주) | C31: 5.5 | D31: 6 | E31: 6 | F31: 6 | G31: 6
A32: (−) 부채 상환 · 기타 투자 | C32: 8 | D32: 10 | E32: 10 | F32: 10 | G32: 10 | H32: 부채 상환 + M&A/전략투자 등 가정 (입력)
A33: 조달 전 기말 현금 ($B) | C33: =C26+C27+C28+C29-C30-C31-C32 -> 159.125 | D33: =D26+D27+D28+D29-D30-D31-D32 -> 230.675 | E33: =E26+E27+E28+E29-E30-E31-E32 -> 304.38825 | F33: =F26+F27+F28+F29-F30-F31-F32 -> 382.41864 | G33: =G26+G27+G28+G29-G30-G31-G32 -> 467.78969
A34: 최소 유지 현금 | B34: 40 | C34: =$B$34 -> 40 | D34: =$B$34 -> 40 | E34: =$B$34 -> 40 | F34: =$B$34 -> 40 | G34: =$B$34 -> 40
A35: 추가 조달 필요액 — 플러그 ($B) | C35: =MAX(0,C34-C33) -> 0 | D35: =MAX(0,D34-D33) -> 0 | E35: =MAX(0,E34-E33) -> 0 | F35: =MAX(0,F34-F33) -> 0 | G35: =MAX(0,G34-G33) -> 0 | H35: 조달 전 현금이 최소치 미만이면 부족분을 자동 조달(부채 가정)해 기말현금에 가산. 총부채에도 반영
A36: 기말 현금 ($B) | C36: =C33+C35 -> 159.125 | D36: =D33+D35 -> 230.675 | E36: =E33+E35 -> 304.38825 | F36: =F33+F35 -> 382.41864 | G36: =G33+G35 -> 467.78969
A37: 지표
A38: FCF (OCF − 현금 capex) | B38: =B10-B23 -> 42.24 | C38: =C10-C23 -> 12.875 | D38: =D10-D23 -> 14.1375 | E38: =E10-E23 -> 17.29125 | F38: =F10-F23 -> 23.614628 | G38: =G10-G23 -> 33.934502
A39: 총부채 (온밸런스, $B) | B39: 84 | C39: =B39+C28+C35-3 -> 126 | D39: =C39+D28+D35-5 -> 161 | E39: =D39+E28+E35-5 -> 191 | F39: =E39+F28+F35-5 -> 216 | G39: =F39+G28+G35-5 -> 236 | H39: 2025A 입력; 이후 = 전기 + 발행 + 플러그 − 상환(상환액 고정: 3,5,5,5,5)
A40: 누적 리스/JV 잔액 ($B) | B40: 0 | C40: =B40+C29 -> 24.75 | D40: =C40+D29 -> 58.1625 | E40: =D40+E29 -> 95.5845 | F40: =E40+F29 -> 136.00026 | G40: =F40+G29 -> 178.43681
A41: 총부채 / OCF | B41: =IF(B10=0,0,B39/B10) -> 0.80367394 | C41: =IF(C10=0,0,C39/C10) -> 1.0029851 | D41: =IF(D10=0,0,D39/D10) -> 1.1048207 | E41: =IF(E10=0,0,E39/E10) -> 1.1599008 | F41: =IF(F10=0,0,F39/F10) -> 1.18173 | G41: =IF(G10=0,0,G39/G10) -> 1.1737722
A42: (총부채+리스/JV) / OCF | B42: =IF(B10=0,0,(B39+B40)/B10) -> 0.80367394 | C42: =IF(C10=0,0,(C39+C40)/C10) -> 1.2 | D42: =IF(D10=0,0,(D39+D40)/D10) -> 1.5039458 | E42: =IF(E10=0,0,(E39+E40)/E10) -> 1.7403644 | F42: =IF(F10=0,0,(F39+F40)/F10) -> 1.9257837 | G42: =IF(G10=0,0,(G39+G40)/G10) -> 2.0612475
A44: Capex 성장률 기본값 (Base 입력) | D44: 0.2 | E44: 0.12 | F44: 0.08 | G44: 0.05 | H44: 2027E~ capex 성장률 기본 가정 (시나리오 조정은 Scenario 시트)

Sheet HBM_Inputs
A1: HBM 수요 모델 — 가정 (HBM_Inputs)
A2: 빅4 서버·칩 capex → AI 가속기 대수 → HBM GB → 금액 → 공급사 매출. 노란 셀 = 입력. 수치는 2026-09 기준 공개 자료 + 가정.
A4: A. 칩 스펙: HBM 용량 / 시스템 ASP(칩 1개당 서버 all-in, $K) / HBM 세대
A5: 칩 패밀리 | B5: HBM GB/칩 | C5: ASP 2026E | D5: ASP 2027E | E5: ASP 2028E | F5: ASP 2029E | G5: ASP 2030E | H5: 세대 2026E | I5: 세대 2027E | J5: 세대 2028E | K5: 세대 2029E | L5: 세대 2030E
A6: NVIDIA Blackwell (B200/B300) | B6: 240 | C6: 40 | D6: 36 | E6: 32 | F6: 30 | G6: 28 | H6: HBM3E | I6: HBM3E | J6: HBM3E | K6: HBM3E | L6: HBM3E
A7: NVIDIA Rubin (VR200) | B7: 288 | C7: 50 | D7: 47 | E7: 44 | F7: 41 | G7: 38 | H7: HBM4 | I7: HBM4 | J7: HBM4 | K7: HBM4 | L7: HBM4
A8: NVIDIA Rubin Ultra / Feynman | B8: 384 | C8: 60 | D8: 60 | E8: 56 | F8: 52 | G8: 48 | H8: HBM4E | I8: HBM4E | J8: HBM4E | K8: HBM4E | L8: HBM4E
A9: Google TPU (v7 Ironwood~) | B9: 216 | C9: 12 | D9: 12 | E9: 11 | F9: 11 | G9: 10 | H9: HBM3E | I9: HBM4 | J9: HBM4 | K9: HBM4E | L9: HBM4E
A10: AWS Trainium (2/3) | B10: 144 | C10: 8 | D10: 9 | E10: 9 | F10: 9 | G10: 9 | H10: HBM3E | I10: HBM4 | J10: HBM4 | K10: HBM4 | L10: HBM4E
A11: 기타 (AMD MI/ MTIA / Maia) | B11: 256 | C11: 30 | D11: 30 | E11: 28 | F11: 26 | G11: 24 | H11: HBM3E | I11: HBM4 | J11: HBM4 | K11: HBM4E | L11: HBM4E
A12: 출처/메모: B200 192GB→B300 288GB HBM3E(블렌드 240GB), Rubin 288GB HBM4, Rubin Ultra 384GB(TrendForce 2026-06), ASIC HBM/칩 96/192→216/288GB 업그레이드(TrendForce). ASP는 랙 시스템가 ÷ GPU 수 기준 추정.
A14: B. HBM 가격 ($/GB) — 세대별
A15: 세대 | C15: 2026E | D15: 2027E | E15: 2028E | F15: 2029E | G15: 2030E
A16: HBM3E | C16: 10 | D16: 13 | E16: 12 | F16: 11 | G16: 10
A17: HBM4 | C17: 15 | D17: 20 | E17: 18 | F17: 16 | G17: 14
A18: HBM4E | C18: 22 | D18: 24 | E18: 22 | F18: 20 | G18: 18
A19: 평균 스택 용량 (GB/스택) | C19: 36 | D19: 40 | E19: 44 | F19: 48 | G19: 48
A20: 출처/메모: HBM3E ~$300/36GB 스택(≈$8~10/GB), HBM4 ~$550/36GB(≈$15/GB) (Silicon Analysts 2026-08). TrendForce(2026-06): 2027 HBM 계약가 '수 배' 급등 전망 → 2027 피크 후 완만 하락 가정. 12-Hi 36GB → 16-Hi 48GB 전환.
A22: C. 공급사 점유율 (매출 기준)
A23: 공급사 | C23: 2026E | D23: 2027E | E23: 2028E | F23: 2029E | G23: 2030E
A24: SK hynix | C24: 0.5 | D24: 0.47 | E24: 0.45 | F24: 0.44 | G24: 0.43
A25: Samsung | C25: 0.32 | D25: 0.34 | E25: 0.35 | F25: 0.36 | G25: 0.36
A26: Micron | C26: 0.18 | D26: 0.19 | E26: 0.2 | F26: 0.2 | G26: 0.21
A27: 합계 체크 (=100%) | C27: =SUM(C24:C26) -> 1 | D27: =SUM(D24:D26) -> 1 | E27: =SUM(E24:E26) -> 1 | F27: =SUM(F24:F26) -> 1 | G27: =SUM(G24:G26) -> 1
A28: 출처: Counterpoint 2Q26 HBM 매출 점유율 SK hynix 50% / Samsung 33% / Micron 18% (2026-09-03). 삼성 HBM4 선행 양산으로 점유율 상승 추세 반영.
A30: D. 시장 범위
A31: 빅4가 전체 HBM 수요에서 차지하는 비중 | C31: 0.55 | D31: 0.55 | E31: 0.55 | F31: 0.55 | G31: 0.55
A32: 메모: 나머지는 오라클·네오클라우드·소버린·xAI/OpenAI 자체·중국·엔터프라이즈 등. 전체 시장 환산용 가정.
A34: E. 회사별: 서버·칩 capex 중 AI 가속기(GPU/ASIC 시스템) 비중
A35: MSFT | B35: 0.7 | H35: 메모: 서버 capex에는 CPU 서버·스토리지·메모리 단품 등도 포함. AMZN은 리테일 IT 포함이라 낮게.
A36: GOOGL | B36: 0.75
A37: AMZN | B37: 0.6
A38: META | B38: 0.8
A40: F. 회사별 AI 가속기 capex 칩 믹스 (금액 기준, 합계 100%)
A41: MSFT | C41: 2026E | D41: 2027E | E41: 2028E | F41: 2029E | G41: 2030E
A42: NVIDIA Blackwell (B200/B300) | C42: 0.6 | D42: 0.25 | E42: 0.05 | F42: 0 | G42: 0
A43: NVIDIA Rubin (VR200) | C43: 0.25 | D43: 0.45 | E43: 0.4 | F43: 0.25 | G43: 0.15
A44: NVIDIA Rubin Ultra / Feynman | C44: 0 | D44: 0.15 | E44: 0.35 | F44: 0.45 | G44: 0.5
A45: Google TPU (v7 Ironwood~) | C45: 0 | D45: 0 | E45: 0 | F45: 0 | G45: 0
A46: AWS Trainium (2/3) | C46: 0 | D46: 0 | E46: 0 | F46: 0 | G46: 0
...

Sheet HBM_Demand
A1: HBM 수요 및 공급사 매출 추정
A2: 단위: 가속기 백만 개, HBM EB(엑사바이트), 스택 백만 개, $B. 초록 = 링크, 검정 = 계산.
A3: ="현재 시나리오: "&Scenario!C4 -> 현재 시나리오: Base
A4: 요약 | C4: 2026E | D4: 2027E | E4: 2028E | F4: 2029E | G4: 2030E
A5: 빅4 합산
A6: AI 가속기 capex ($B) | C6: =C42+C74+C106+C138 -> 311.775 | D6: =D42+D74+D106+D138 -> 387.23375 | E6: =E42+E74+E106+E138 -> 436.76774 | F6: =F42+F74+F106+F138 -> 476.68938 | G6: =G42+G74+G106+G138 -> 500.52384
A7: AI 가속기 대수 (백만 개) | C7: =C50+C82+C114+C146 -> 14.378767 | D7: =D50+D82+D114+D146 -> 17.486448 | E7: =E50+E82+E114+E146 -> 21.107159 | F7: =F50+F82+F114+F146 -> 24.217122 | G7: =G50+G82+G114+G146 -> 27.345871
A8: HBM 수요 (EB) | C8: =C58+C90+C122+C154 -> 2.9792795 | D8: =D58+D90+D122+D154 -> 3.7982041 | E8: =E58+E90+E122+E154 -> 4.6883127 | F8: =F58+F90+F122+F154 -> 5.4456214 | G8: =G58+G90+G122+G154 -> 6.1970927
A9: YoY | D9: =IF(C8=0,0,D8/C8-1) -> 0.27487338 | E9: =IF(D8=0,0,E8/D8-1) -> 0.23434986 | F9: =IF(E8=0,0,F8/E8-1) -> 0.16153117 | G9: =IF(F8=0,0,G8/F8-1) -> 0.13799552
A10: HBM 스택 수 (백만 개) | C10: =C8*1000/HBM_Inputs!C19 -> 82.757763 | D10: =D8*1000/HBM_Inputs!D19 -> 94.955102 | E10: =E8*1000/HBM_Inputs!E19 -> 106.55256 | F10: =F8*1000/HBM_Inputs!F19 -> 113.45044 | G10: =G8*1000/HBM_Inputs!G19 -> 129.1061
A11: HBM 금액 ($B) | C11: =C66+C98+C130+C162 -> 31.420679 | D11: =D66+D98+D130+D162 -> 73.815877 | E11: =E66+E98+E130+E162 -> 86.398938 | F11: =F66+F98+F130+F162 -> 102.24344 | G11: =G66+G98+G130+G162 -> 109.78436
A12: 평균 $/GB (블렌드) | C12: =IF(C8=0,0,C11/C8) -> 10.546402 | D12: =IF(D8=0,0,D11/D8) -> 19.434416 | E12: =IF(E8=0,0,E11/E8) -> 18.428578 | F12: =IF(F8=0,0,F11/F8) -> 18.775349 | G12: =IF(G8=0,0,G11/G8) -> 17.715461
A13: HBM / AI 가속기 capex | C13: =IF(C6=0,0,C11/C6) -> 0.10077998 | D13: =IF(D6=0,0,D11/D6) -> 0.19062356 | E13: =IF(E6=0,0,E11/E6) -> 0.19781438 | F13: =IF(F6=0,0,F11/F6) -> 0.21448652 | G13: =IF(G6=0,0,G11/G6) -> 0.21933891
A14: HBM3E 금액 ($B) | C14: =C68+C100+C132+C164 -> 26.537027 | D14: =D68+D100+D132+D164 -> 6.0453846 | E14: =E68+E100+E132+E164 -> 1.7232648 | F14: =F68+F100+F132+F164 -> 0 | G14: =G68+G100+G132+G164 -> 0
A15: HBM4 금액 ($B) | C15: =C69+C101+C133+C165 -> 4.883652 | D15: =D69+D101+D133+D165 -> 61.128481 | E15: =E69+E101+E133+E165 -> 68.885494 | F15: =F69+F101+F133+F165 -> 26.675936 | G15: =G69+G101+G133+G165 -> 6.1715902
A16: HBM4E 금액 ($B) | C16: =C70+C102+C134+C166 -> 0 | D16: =D70+D102+D134+D166 -> 6.6420115 | E16: =E70+E102+E134+E166 -> 15.790179 | F16: =F70+F102+F134+F166 -> 75.567507 | G16: =G70+G102+G134+G166 -> 103.61277
A18: 회사별 HBM 금액 ($B)
A19: MSFT | C19: =C66 -> 5.77808 | D19: =D66 -> 12.870961 | E19: =E66 -> 15.720244 | F19: =F66 -> 19.343855 | G19: =G66 -> 20.506677
A20: GOOGL | C20: =C98 -> 12.1176 | D20: =D98 -> 30.990801 | E20: =E98 -> 36.378511 | F20: =F98 -> 45.41992 | G20: =G98 -> 47.157478
A21: AMZN | C21: =C130 -> 9.342432 | D21: =D130 -> 20.846039 | E21: =E130 -> 23.132667 | F21: =F130 -> 23.987819 | G21: =G130 -> 27.817315
A22: META | C22: =C162 -> 4.1825667 | D22: =D162 -> 9.1080768 | E22: =E162 -> 11.167517 | F22: =F162 -> 13.491848 | G22: =G162 -> 14.302887
A24: 전체 시장 환산 및 공급사 매출
A25: 글로벌 HBM 시장 ($B) = 빅4 ÷ 빅4 비중 | C25: =IF((HBM_Inputs!C31+Scenario!C$41)=0,0,C11/(HBM_Inputs!C31+Scenario!C$41)) -> 57.128507 | D25: =IF((HBM_Inputs!D31+Scenario!D$41)=0,0,D11/(HBM_Inputs!D31+Scenario!D$41)) -> 134.21069 | E25: =IF((HBM_Inputs!E31+Scenario!E$41)=0,0,E11/(HBM_Inputs!E31+Scenario!E$41)) -> 157.08898 | F25: =IF((HBM_Inputs!F31+Scenario!F$41)=0,0,F11/(HBM_Inputs!F31+Scenario!F$41)) -> 185.89717 | G25: =IF((HBM_Inputs!G31+Scenario!G$41)=0,0,G11/(HBM_Inputs!G31+Scenario!G$41)) -> 199.60792
A26: YoY | D26: =IF(C25=0,0,D25/C25-1) -> 1.349277 | E26: =IF(D25=0,0,E25/D25-1) -> 0.17046551 | F26: =IF(E25=0,0,F25/E25-1) -> 0.18338773 | G26: =IF(F25=0,0,G25/F25-1) -> 0.073754497
A27: 글로벌 HBM 수요 (EB) | C27: =IF((HBM_Inputs!C31+Scenario!C$41)=0,0,C8/(HBM_Inputs!C31+Scenario!C$41)) -> 5.4168718 | D27: =IF((HBM_Inputs!D31+Scenario!D$41)=0,0,D8/(HBM_Inputs!D31+Scenario!D$41)) -> 6.9058256 | E27: =IF((HBM_Inputs!E31+Scenario!E$41)=0,0,E8/(HBM_Inputs!E31+Scenario!E$41)) -> 8.5242049 | F27: =IF((HBM_Inputs!F31+Scenario!F$41)=0,0,F8/(HBM_Inputs!F31+Scenario!F$41)) -> 9.9011297 | G27: =IF((HBM_Inputs!G31+Scenario!G$41)=0,0,G8/(HBM_Inputs!G31+Scenario!G$41)) -> 11.267441
A28: SK hynix HBM 매출 ($B) | C28: =C25*(HBM_Inputs!C24-Scenario!C$47) -> 28.564253 | D28: =D25*(HBM_Inputs!D24-Scenario!D$47) -> 63.079022 | E28: =E25*(HBM_Inputs!E24-Scenario!E$47) -> 70.69004 | F28: =F25*(HBM_Inputs!F24-Scenario!F$47) -> 81.794754 | G28: =G25*(HBM_Inputs!G24-Scenario!G$47) -> 85.831406
A29: Samsung HBM 매출 ($B) | C29: =C25*(HBM_Inputs!C25+Scenario!C$47) -> 18.281122 | D29: =D25*(HBM_Inputs!D25+Scenario!D$47) -> 45.631633 | E29: =E25*(HBM_Inputs!E25+Scenario!E$47) -> 54.981142 | F29: =F25*(HBM_Inputs!F25+Scenario!F$47) -> 66.922981 | G29: =G25*(HBM_Inputs!G25+Scenario!G$47) -> 71.858852
A30: Micron HBM 매출 ($B) | C30: =C25*HBM_Inputs!C26 -> 10.283131 | D30: =D25*HBM_Inputs!D26 -> 25.50003 | E30: =E25*HBM_Inputs!E26 -> 31.417796 | F30: =F25*HBM_Inputs!F26 -> 37.179434 | G30: =G25*HBM_Inputs!G26 -> 41.917663
A31: (참고) 빅4 향 매출만: 위 × 빅4 비중
A32: SK hynix — 빅4 향 ($B) | C32: =C11*(HBM_Inputs!C24-Scenario!C$47) -> 15.710339 | D32: =D11*(HBM_Inputs!D24-Scenario!D$47) -> 34.693462 | E32: =E11*(HBM_Inputs!E24-Scenario!E$47) -> 38.879522 | F32: =F11*(HBM_Inputs!F24-Scenario!F$47) -> 44.987115 | G32: =G11*(HBM_Inputs!G24-Scenario!G$47) -> 47.207273
A33: Samsung — 빅4 향 ($B) | C33: =C11*(HBM_Inputs!C25+Scenario!C$47) -> 10.054617 | D33: =D11*(HBM_Inputs!D25+Scenario!D$47) -> 25.097398 | E33: =E11*(HBM_Inputs!E25+Scenario!E$47) -> 30.239628 | F33: =F11*(HBM_Inputs!F25+Scenario!F$47) -> 36.807639 | G33: =G11*(HBM_Inputs!G25+Scenario!G$47) -> 39.522368
A34: Micron — 빅4 향 ($B) | C34: =C11*HBM_Inputs!C26 -> 5.6557222 | D34: =D11*HBM_Inputs!D26 -> 14.025017 | E34: =E11*HBM_Inputs!E26 -> 17.279788 | F34: =F11*HBM_Inputs!F26 -> 20.448689 | G34: =G11*HBM_Inputs!G26 -> 23.054715
A36: 메모: 교차검증 — TrendForce 2026 HBM 수요 +70% 전망, HBM4 가 2027 주력. 모델의 글로벌 HBM 금액이 업계 전망($50~70B 수준, 2026)과 크게 다르면 ASP/가속기 비중/$/GB를 먼저 점검.
A37: 시나리오: Scenario 시트 B4 선택값에 따라 가속기 비중·ASP·GB/칩·$/GB·빅4 비중·삼성 점유율이 조정됨 (HBM_Inputs 값은 Base 기준).
A40: MSFT — 서버·칩 capex → 가속기 → HBM | C40: 2026E | D40: 2027E | E40: 2028E | F40: 2029E | G40: 2030E
A41: 서버·칩 capex ($B) | C41: =MSFT!C19 -> 117.25 | D41: =MSFT!D19 -> 146.5625 | E41: =MSFT!E19 -> 163.51562 | F41: =MSFT!F19 -> 179.86719 | G41: =MSFT!G19 -> 188.86055
A42: AI 가속기 capex ($B) | C42: =C41*(HBM_Inputs!$B$35+Scenario!C$17) -> 82.075 | D42: =D41*(HBM_Inputs!$B$35+Scenario!D$17) -> 102.59375 | E42: =E41*(HBM_Inputs!$B$35+Scenario!E$17) -> 114.46094 | F42: =F41*(HBM_Inputs!$B$35+Scenario!F$17) -> 125.90703 | G42: =G41*(HBM_Inputs!$B$35+Scenario!G$17) -> 132.20238
A43: 가속기 대수 (백만 개)
A44: NVIDIA Blackwell (B200/B300) | C44: =IF(HBM_Inputs!C6=0,0,C42*HBM_Inputs!C42/(HBM_Inputs!C6*Scenario!C$35)) -> 1.231125 | D44: =IF(HBM_Inputs!D6=0,0,D42*HBM_Inputs!D42/(HBM_Inputs!D6*Scenario!D$35)) -> 0.7124566 | E44: =IF(HBM_Inputs!E6=0,0,E42*HBM_Inputs!E42/(HBM_Inputs!E6*Scenario!E$35)) -> 0.17884521 | F44: =IF(HBM_Inputs!F6=0,0,F42*HBM_Inputs!F42/(HBM_Inputs!F6*Scenario!F$35)) -> 0 | G44: =IF(HBM_Inputs!G6=0,0,G42*HBM_Inputs!G42/(HBM_Inputs!G6*Scenario!G$35)) -> 0
A45: NVIDIA Rubin (VR200) | C45: =IF(HBM_Inputs!C7=0,0,C42*HBM_Inputs!C43/(HBM_Inputs!C7*Scenario!C$35)) -> 0.410375 | D45: =IF(HBM_Inputs!D7=0,0,D42*HBM_Inputs!D43/(HBM_Inputs!D7*Scenario!D$35)) -> 0.98228059 | E45: =IF(HBM_Inputs!E7=0,0,E42*HBM_Inputs!E43/(HBM_Inputs!E7*Scenario!E$35)) -> 1.040554 | F45: =IF(HBM_Inputs!F7=0,0,F42*HBM_Inputs!F43/(HBM_Inputs!F7*Scenario!F$35)) -> 0.7677258 | G45: =IF(HBM_Inputs!G7=0,0,G42*HBM_Inputs!G43/(HBM_Inputs!G7*Scenario!G$35)) -> 0.52185151
...
